Workbook

Sheet Read Me
A1: Bryan J. Freedman (SBN 151990) — Consolidated Trellis Data
A4: What this is | B4: One consolidated workbook built from 11 Trellis exports (8 scraped case-list pages, 2 xlsx, 1 csv) plus the BC606196 docket PDF.
A5: Unique cases | B5: 322 after de-duplicating on case number across all source files (470 raw rows ingested).
A7: TABS
A8: All Cases | B8: Every unique case: name, no., filed date, judge, Trellis disposition, an Outcome Bucket, practice area, matter type, court, source file, URL.
A9: Judge Summary | B9: Per-judge appearance counts + disposition breakdown (formulas count live off the All Cases tab).
A10: Disposition Summary | B10: Counts by raw Trellis disposition and by Outcome Bucket.
A11: Liberty BC606196 | B11: The one case you pulled a full 130-pg docket for — case facts + party-level dispositions.
A13: READ THIS — what the data can and cannot tell you
A14: Appearance counts are reliable. | B14: Who Freedman/Freedman+Taitelman has been in front of, and how often, is solid.
A15: Win/loss is NOT in this data. | B15: The only outcome field is case disposition. "Dismissal" is directionally ambiguous (settlement, voluntary, defense win, or plaintiff loss) and which side Freedman was on is not encoded.
A16: Counts include the firm collections docket. | B16: Many rows are Freedman+Taitelman / Banco Popular / Dreier Stein collections matters where the firm was a party. There "Default Judgment" = the firm collecting a debt, not courtroom advocacy. This inflates several judges.
A17: On your "8–12 times" recollection | B17: In the deduped data, only Maureen Duffy-Lewis reaches that band (11). Then a tight cluster of four judges at 7 (Hiroshige, Wiley, Linfield, Green). Trellis’s own profile likely shows higher per-judge numbers because it counts non-deduped appearances/rulings and the firm-as-party docket.
A18: Real merits signal | B18: Lives at the motion/ruling level (e.g., the BC606196 docket), not in these summary cards.

Sheet All Cases
A1: Case Name | B1: Case No | C1: Filed | D1: Judge | E1: Disposition (Trellis) | F1: Outcome Bucket | G1: Practice Area | H1: Matter Type | I1: Court | J1: Source File | K1: URL
A2: MARK YOUSSEF VS KELLY MULHERN ET AL | B2: BC427361 | C2: Dec 04, 2009 | D2: Hon. Abraham Khan | E2: Dismissal | F2: Dismissed/Withdrawn | I2: Stanley Mosk Courthouse | J2: clean_trellis__10__judges-6.xlsx | K2: https://trellis.law/case/bc427361/mark-youssef-vs-kelly-mulhern-et-al
A3: DREIER STEIN KAHAN BROWNE WOODS GEORGE LLP ET AL VS IMAGE EN | B3: BC432833 | C3: Feb 26, 2010 | D3: Hon. Abraham Khan | E3: Dismissal | F3: Dismissed/Withdrawn | G3: Commercial | H3: Breach of Contract | I3: Stanley Mosk Courthouse | J3: clean_trellis__10__judges-2.xlsx | K3: https://trellis.law/case/bc432833/dreier-stein-kahan-browne-woods-george-llp-et-al-vs-image-en
A4: KHALIL RAFATI VS DOES 1 THROUGH 25 | B4: BC509261 | C4: May 17, 2013 | D4: Hon. Abraham Khan | E4: Dismissal | F4: Dismissed/Withdrawn | G4: Torts | H4: Slander,Libel,Defamation | I4: Stanley Mosk Courthouse | J4: clean_trellis__10__judges-1.xlsx | K4: https://trellis.law/case/bc509261/khalil-rafati-vs-does-1-through-25
A5: EH BUTLAND DEVELOPMENT CORP VS JANSS COURT ASSOCIATES LLC | B5: BC263303 | C5: Dec 10, 2001 | D5: Hon. Alban I. Niles | E5: Dismissal | F5: Dismissed/Withdrawn | G5: Creditor | H5: Collections | I5: Stanley Mosk Courthouse | J5: trellis.csv | K5: https://trellis.law/case/bc263303/eh-butland-development-corp-vs-janss-court-associates-llc
A6: RORY POSIN VS BENJAMIN BELLET ET AL | B6: BC490353 | C6: Aug 15, 2012 | D6: Hon. Amy D. Hogue | E6: Dismissal | F6: Dismissed/Withdrawn | G6: Securities | H6: Business Governance | I6: Stanley Mosk Courthouse | J6: trellis.csv | K6: https://trellis.law/case/bc490353/rory-posin-vs-benjamin-bellet-et-al
A7: BANCO POPULAR NORTH AMERICA VS R & J LEGAL SERVICES INC ET A | B7: BC396705 | C7: Aug 20, 2008 | D7: Hon. Amy D. Hogue | E7: Default Judgment | F7: Default Judgment | G7: Commercial | H7: Breach of Contract | I7: Stanley Mosk Courthouse | J7: clean_trellis__10__judges-6.xlsx | K7: https://trellis.law/case/bc396705/banco-popular-north-america-vs-r-j-legal-services-inc-et-a
A8: BANCO POPULAR NORTH AMERICA VS DAELIM INSURANCE AGENCY INC | B8: BC398874 | C8: Jan 09, 2008 | D8: Hon. Amy D. Hogue | E8: Dismissal | F8: Dismissed/Withdrawn | G8: Commercial | H8: Breach of Contract | I8: Stanley Mosk Courthouse | J8: clean_trellis__10__judges-1.xlsx | K8: https://trellis.law/case/bc398874/banco-popular-north-america-vs-daelim-insurance-agency-inc
A9: DREIER STEIN KAHAN BROWNE WOODS GEORGE LLP VS SEOUL NATIONAL | B9: BC433001 | C9: Mar 03, 2010 | D9: Hon. Amy D. Hogue | E9: Dismissal | F9: Dismissed/Withdrawn | G9: Commercial | H9: Breach of Contract | I9: Stanley Mosk Courthouse | J9: clean_trellis__10__judges-6.xlsx | K9: https://trellis.law/case/bc433001/dreier-stein-kahan-browne-woods-george-llp-vs-seoul-national
A10: DREIER STEIN KAHAN BROWNE WOODS GEORGE LLP VS LIOLIOS GROUP | B10: BC434484 | C10: Mar 24, 2010 | D10: Hon. Amy D. Hogue | E10: Dismissal | F10: Dismissed/Withdrawn | G10: Commercial | H10: Breach of Contract | I10: Stanley Mosk Courthouse | J10: clean_trellis__10__judges-1.xlsx | K10: https://trellis.law/case/bc434484/dreier-stein-kahan-browne-woods-george-llp-vs-liolios-group
A11: ST. ANDREWS SECOND HOME LLC, A DELAWARE LIMITED LIABILITY COMPANY VS SECOND HOME US INC., A DELAWARE CORPORATION, ET AL. | B11: 23STCV09293 | C11: Apr 26, 2023 | D11: Hon. Armen Tamzarian | E11: Active | F11: Active | G11: Property | H11: Unlawful Detainer | I11: Stanley Mosk | J11: trellis.xlsx | K11: https://trellis.law/case/23stcv09293/st-andrews-second-home-llc-a-delaware-limited-liability-company-vs-second-home-us-inc-a-delaware-corporation-et-al
A12: REGENCY SAVINGS BANK FSB VS PHILIP A ROSTER | B12: BC191770 | C12: May 28, 1998 | D12: Hon. Arnold Levin | E12: Dismissal | F12: Dismissed/Withdrawn | I12: Stanley Mosk Courthouse | J12: trellis.csv | K12: https://trellis.law/case/bc191770/regency-savings-bank-fsb-vs-philip-a-roster
A13: OLD CHURCH LLC ET AL VS FAR EAST NATIONAL BANK | B13: BC486656 | C13: Jun 14, 2012 | D13: Hon. Barbara Marie Scheper | E13: Summary Judgment | F13: Merits/Judgment | G13: Commercial | H13: Contractual Fraud | I13: Stanley Mosk Courthouse | J13: clean_trellis__10__judges-6.xlsx | K13: https://trellis.law/case/bc486656/old-church-llc-et-al-vs-far-east-national-bank
A14: FREEDMAN & TAITELMAN LLP VS JEDAMIST ET AL | B14: BC458020 | C14: Mar 23, 2011 | D14: Hon. Barbara Marie Scheper | E14: Dismissal | F14: Dismissed/Withdrawn | G14: Commercial | H14: Breach of Contract | I14: Stanley Mosk Courthouse | J14: trellis-_F_T_-49rows.xlsx | K14: https://trellis.law/case/bc458020/freedman-taitelman-llp-vs-jedamist-et-al
A15: LEE & ASSOC COMMERCIAL REAL ESTATE ET AL VS DENNIS SWANSON | B15: BC493574 | C15: Oct 12, 2012 | D15: Hon. Barbara Marie Scheper | E15: Dismissal | F15: Dismissed/Withdrawn | G15: Property | H15: Unlawful Detainer | I15: Stanley Mosk Courthouse | J15: trellis.csv | K15: https://trellis.law/case/bc493574/lee-assoc-commercial-real-estate-et-al-vs-dennis-swanson
A16: GATEWAY BUSINESS BANK VS E F J ENTERPRISE, INC., ET AL | B16: VC039137 | C16: Jan 24, 2003 | D16: Hon. Brian F. Gasdia | E16: Dismissal | F16: Dismissed/Withdrawn | G16: Commercial | H16: Contractual Fraud | I16: Norwalk Courthouse | J16: trellis.xlsx | K16: https://trellis.law/case/vc039137/gateway-business-bank-vs-e-f-j-enterprise-inc-et-al
A17: HUDSON 604 ARIZONA LLC VS REAL OFFICE CENTERS CORP ET AL | B17: BC549149 | C17: Jun 18, 2014 | D17: Hon. Brian S. Currey | E17: Dismissal | F17: Dismissed/Withdrawn | G17: Property | H17: Unlawful Detainer | I17: Stanley Mosk Courthouse | J17: clean_trellis__10__judges-2.xlsx | K17: https://trellis.law/case/bc549149/hudson-604-arizona-llc-vs-real-office-centers-corp-et-al
A18: G.J. DESIGN INC VS PDTW LLC ET AL | B18: BC473809 | C18: Nov 18, 2011 | D18: Hon. Brian S. Currey | E18: Dismissal | F18: Dismissed/Withdrawn | G18: Commercial | H18: Breach of Contract | I18: Stanley Mosk Courthouse | J18: clean_trellis__10__judges-2.xlsx | K18: https://trellis.law/case/bc473809/g-j-design-inc-vs-pdtw-llc-et-al
A19: BANKERS TRUST CO OF CALIF N A VS NOELETHA E LACEY ET AL | B19: BC186587 | C19: Feb 25, 1998 | D19: Hon. Bruce E. Mitchell | E19: Dismissal | F19: Dismissed/Withdrawn | G19: Property | H19: General Property | I19: Stanley Mosk Courthouse | J19: trellis.csv | K19: https://trellis.law/case/bc186587/bankers-trust-co-calif-n-a-vs-noeletha-e-lacey-et-al
A20: SUPERIOR STUCCO & PLASTERING VS. ANDREW CHERNG | B20: GC039002 | C20: May 17, 2007 | D20: Hon. C. Edward Simpson | E20: Dismissal | F20: Dismissed/Withdrawn | I20: Pasadena Courthouse | J20: trellis-_F_T_-49rows.xlsx | K20: https://trellis.law/case/gc039002/superior-stucco-plastering-vs-andrew-cherng
A21: DONALD BROWN VS ALBERTSONS INC | B21: BC294155 | C21: Apr 17, 2003 | D21: Hon. Carl J. West | E21: Dismissal | F21: Dismissed/Withdrawn | G21: Labor and Employment | H21: General Employment | I21: Stanley Mosk Courthouse | J21: trellis.xlsx | K21: https://trellis.law/case/bc294155/donald-brown-vs-albertsons-inc
A22: MARINA HANTZIS VS. JAMES C. BOZZUTO | B22: BS135009 | C22: Dec 20, 2011 | D22: Hon. Carol Boas Goodson | E22: Dismissal | F22: Dismissed/Withdrawn | G22: Torts | H22: Harassment | I22: Stanley Mosk Courthouse | J22: clean_trellis__10__judges-1.xlsx | K22: https://trellis.law/case/bs135009/marina-hantzis-vs-james-c-bozzuto
A23: ALYSON HANNINGAN VS. JOHN HOBBS | B23: BS141494 | C23: Feb 13, 2013 | D23: Hon. Carol Boas Goodson | E23: Judgment (Other) | F23: Merits/Judgment | G23: Torts | H23: Harassment | I23: Stanley Mosk Courthouse | J23: clean_trellis__10__judges-1.xlsx | K23: https://trellis.law/case/bs141494/alyson-hanningan-vs-john-hobbs
A24: RANNIE ANN RODIL VS ROBERT BASSIRI | B24: BS125418 | C24: Mar 16, 2010 | D24: Hon. Carol Boas Goodson | E24: Dismissal | F24: Dismissed/Withdrawn | G24: Torts | H24: Harassment | I24: Stanley Mosk Courthouse | J24: clean_trellis__10__judges-1.xlsx | K24: https://trellis.law/case/bs125418/rannie-ann-rodil-vs-robert-bassiri
A25: EDDIE KWOH VS PAPA ANTONIOS INC ET AL | B25: BC185203 | C25: Jan 30, 1998 | D25: Hon. Carolyn B. Kuhl | E25: Default Judgment | F25: Default Judgment | G25: Commercial | H25: General Commercial | I25: Stanley Mosk Courthouse | J25: trellis.csv | K25: https://trellis.law/case/bc185203/eddie-kwoh-vs-papa-antonios-inc-et-al
A26: SC MANUFACTURED HOMES INC ET AL VS NORMAN SCOTT LIEBERT ET A | B26: BC311686 | C26: Mar 05, 2004 | D26: Hon. Carolyn B. Kuhl | E26: Dismissal | F26: Dismissed/Withdrawn | G26: Antitrust | H26: General Antitrust | I26: Stanley Mosk Courthouse | J26: trellis.xlsx | K26: https://trellis.law/case/bc311686/sc-manufactured-homes-inc-et-al-vs-norman-scott-liebert-et-a
A27: FREEDMAN & TAITELMAN, LLP VS. JANELLE HOLDEN, ET AL | B27: YC056930 | C27: Mar 07, 2008 | D27: Hon. Cary H. Nishimoto | E27: Dismissal | F27: Dismissed/Withdrawn | G27: Commercial | H27: Breach of Contract | I27: Torrance Courthouse | J27: trellis-_F_T_-49rows.xlsx | K27: https://trellis.law/case/yc056930/freedman-taitelman-llp-vs-janelle-holden-et-al
A28: DREIER STEIN KAHAN BROWNE WOODS GEORGE LLP ET AL VS NOBLE EN | B28: BC432802 | C28: Feb 26, 2010 | D28: Hon. Charles F. Palmer | E28: Default Judgment | F28: Default Judgment | G28: Commercial | H28: Breach of Contract | I28: Stanley Mosk Courthouse | J28: clean_trellis__10__judges-3.xlsx | K28: https://trellis.law/case/bc432802/dreier-stein-kahan-browne-woods-george-llp-et-al-vs-noble-en
A29: STEPHEN BARNES VS LAVELY & SINGER ET AL | B29: BC191060 | C29: May 15, 1998 | D29: Hon. Charles W. McCoy, Jr. | E29: Summary Judgment | F29: Merits/Judgment | G29: Torts | H29: Malpractice | I29: Stanley Mosk Courthouse | J29: trellis.csv | K29: https://trellis.law/case/bc191060/stephen-barnes-vs-lavely-singer-et-al
A30: MDS, INC. VS. LANDMARK ENTERTAINMENT GROUP | B30: EC036294 | C30: Feb 25, 2003 | D30: Hon. Charles W. Stoll | E30: Default Judgment | F30: Default Judgment | G30: Commercial | H30: General Commercial | I30: Glendale Courthouse | J30: trellis.csv | K30: https://trellis.law/case/ec036294/mds-inc-vs-landmark-entertainment-group
A31: CHARLES MARMO, ET AL VS. FRANCIS PROPERTY MANAGEMENT | B31: EC042434 | C31: Mar 10, 2006 | D31: Hon. Charles W. Stoll | E31: Want of Prosecution | F31: Dismissed/Withdrawn | G31: Property | H31: Landlord-Tenant | I31: Glendale Courthouse | J31: trellis.csv | K31: https://trellis.law/case/ec042434/charles-marmo-et-al-vs-francis-property-management
A32: SONNY HENTY, ET AL. VS M.MALONE, INC., A CALIFORNIA CORPORATION, ET AL. | B32: 22STCP04455 | C32: Dec 27, 2022 | D32: Hon. Christopher K. Lui | E32: Voluntary Dismissal | F32: Dismissed/Withdrawn | G32: Securities | H32: Business Governance | I32: Stanley Mosk | J32: clean_trellis__10__judges-2.xlsx | K32: https://trellis.law/case/22stcp04455/sonny-henty-et-al-vs-m-malone-inc-a-california-corporation-et-al
... A40: JAMES COPELAND VS RENE GABRIEL HERNANDEZ, ET AL | B40: VC044956 | C40: Aug 04, 2005 | D40: Hon. Daniel S. Pratt | E40: Dismissal | F40: Dismissed/Withdrawn | G40: Torts | H40: Automobile | I40: Norwalk Courthouse | J40: trellis.csv | K40: https://trellis.law/case/vc044956/james-copeland-vs-rene-gabriel-hernandez-et-al
A41: 610 AVENIDA VICTORIA RESTAURANT, LLC VS. MARK GERAGOS | B41: 30-2021-01184881-CU-BC-CJC | C41: Feb 17, 2021 | D41: Hon. David A. Hoffer | E41: Unknown | F41: Other/Unknown | G41: Breach of Contract | I41: Orange County, CA | J41: trellis.csv | K41: https://trellis.law/case/30-2021-01184881-cu-bc-cjc/610-avenida-victoria-restaurant-llc-vs-mark-geragos
A42: 2221 PARK PLACE ASSOCIATES VS DIGITAL MEDIA CAMPUS | B42: BC242152 | C42: Dec 21, 2000 | D42: Hon. David A. Horowitz | E42: Dismissal | F42: Dismissed/Withdrawn | G42: Civil | H42: Injunctive Action | I42: Stanley Mosk Courthouse | J42: trellis.csv | K42: https://trellis.law/case/bc242152/2221-park-place-associates-vs-digital-media-campus
A43: YOUNG, NICOLE VS YOUNG, ANDRE | B43: 20STFL05624 | C43: Jun 29, 2020 | D43: Hon. David J. Cowan | E43: Default Judgment | F43: Default Judgment | G43: Family | H43: Divorce,Separation | I43: Superior | J43: clean_trellis__10__bryan-joel.xlsx | K43: https://trellis.law/case/20stfl05624/young-nicole-vs-young-andre
A44: BRIAN WILLIAM CORMAN ET AL VS ROGER WILLIAM CORMAN ET AL | B44: BC681310 | C44: Oct 26, 2017 | D44: Hon. David J. Cowan | E44: Unknown | F44: Other/Unknown | G44: Torts | H44: Personal Injury | I44: Stanley Mosk Courthouse | J44: trellis.xlsx | K44: https://trellis.law/case/bc681310/brian-william-corman-et-al-vs-roger-william-corman-et-al
A45: SANTA BARBARA BANK & TRUST VS. RAB PRODUCTIONS INC., ET AL | B45: BC290542 | C45: Feb 18, 2003 | D45: Hon. David L. Minning | E45: Dismissal | F45: Dismissed/Withdrawn | G45: Creditor | H45: Collections | I45: Stanley Mosk Courthouse | J45: clean_trellis__10__judges-2.xlsx | K45: https://trellis.law/case/bc290542/santa-barbara-bank-trust-vs-rab-productions-inc-et-al
A46: UNITED TALENT AGENCY INC VS MEDIAMORPH INC ET AL | B46: BC473720 | C46: Nov 17, 2011 | D46: Hon. David L. Minning | E46: Dismissal | F46: Dismissed/Withdrawn | G46: Commercial | H46: Contractual Fraud | I46: Stanley Mosk Courthouse | J46: clean_trellis__10__judges-2.xlsx | K46: https://trellis.law/case/bc473720/united-talent-agency-inc-vs-mediamorph-inc-et-al
A47: MUSE PRODUCTIONS INC., ET AL VS. FRANCIS FORD COPPOLA INC., | B47: BC380989 | C47: Nov 19, 2007 | D47: Hon. David L. Minning | E47: Dismissal | F47: Dismissed/Withdrawn | G47: Commercial | H47: Breach of Contract | I47: Stanley Mosk Courthouse | J47: clean_trellis__10__judges-6.xlsx | K47: https://trellis.law/case/bc380989/muse-productions-inc-et-al-vs-francis-ford-coppola-inc
...

Sheet Judge Summary
A1: Appearances by Judge (counts pull live from the All Cases tab)
A3: Judge | B3: Total Cases | C3: Dismissed/Withdrawn | D3: Default Judgment | E3: Active | F3: Merits/Judgment | G3: Other/Unknown
A4: Hon. Maureen Duffy-Lewis | B4: =COUNTIF('All Cases'!$D$2:$D$323,A4) -> 11 | C4: =COUNTIFS('All Cases'!$D$2:$D$323,A4,'All Cases'!$F$2:$F$323,"Dismissed/Withdrawn") -> 6 | D4: =COUNTIFS('All Cases'!$D$2:$D$323,A4,'All Cases'!$F$2:$F$323,"Default Judgment") -> 2 | E4: =COUNTIFS('All Cases'!$D$2:$D$323,A4,'All Cases'!$F$2:$F$323,"Active") -> 3 | F4: =COUNTIFS('All Cases'!$D$2:$D$323,A4,'All Cases'!$F$2:$F$323,"Merits/Judgment") -> 0 | G4: =COUNTIFS('All Cases'!$D$2:$D$323,A4,'All Cases'!$F$2:$F$323,"Other/Unknown") -> 0
A5: Unknown | B5: =COUNTIF('All Cases'!$D$2:$D$323,A5) -> 10 | C5: =COUNTIFS('All Cases'!$D$2:$D$323,A5,'All Cases'!$F$2:$F$323,"Dismissed/Withdrawn") -> 4 | D5: =COUNTIFS('All Cases'!$D$2:$D$323,A5,'All Cases'!$F$2:$F$323,"Default Judgment") -> 2 | E5: =COUNTIFS('All Cases'!$D$2:$D$323,A5,'All Cases'!$F$2:$F$323,"Active") -> 1 | F5: =COUNTIFS('All Cases'!$D$2:$D$323,A5,'All Cases'!$F$2:$F$323,"Merits/Judgment") -> 1 | G5: =COUNTIFS('All Cases'!$D$2:$D$323,A5,'All Cases'!$F$2:$F$323,"Other/Unknown") -> 2
A6: Hon. Ernest M. Hiroshige | B6: =COUNTIF('All Cases'!$D$2:$D$323,A6) -> 7 | C6: =COUNTIFS('All Cases'!$D$2:$D$323,A6,'All Cases'!$F$2:$F$323,"Dismissed/Withdrawn") -> 5 | D6: =COUNTIFS('All Cases'!$D$2:$D$323,A6,'All Cases'!$F$2:$F$323,"Default Judgment") -> 1 | E6: =COUNTIFS('All Cases'!$D$2:$D$323,A6,'All Cases'!$F$2:$F$323,"Active") -> 0 | F6: =COUNTIFS('All Cases'!$D$2:$D$323,A6,'All Cases'!$F$2:$F$323,"Merits/Judgment") -> 0 | G6: =COUNTIFS('All Cases'!$D$2:$D$323,A6,'All Cases'!$F$2:$F$323,"Other/Unknown") -> 1
A7: Hon. John Shepard Wiley, Jr. | B7: =COUNTIF('All Cases'!$D$2:$D$323,A7) -> 7 | C7: =COUNTIFS('All Cases'!$D$2:$D$323,A7,'All Cases'!$F$2:$F$323,"Dismissed/Withdrawn") -> 6 | D7: =COUNTIFS('All Cases'!$D$2:$D$323,A7,'All Cases'!$F$2:$F$323,"Default Judgment") -> 0 | E7: =COUNTIFS('All Cases'!$D$2:$D$323,A7,'All Cases'!$F$2:$F$323,"Active") -> 0 | F7: =COUNTIFS('All Cases'!$D$2:$D$323,A7,'All Cases'!$F$2:$F$323,"Merits/Judgment") -> 1 | G7: =COUNTIFS('All Cases'!$D$2:$D$323,A7,'All Cases'!$F$2:$F$323,"Other/Unknown") -> 0
A8: Hon. Michael P. Linfield | B8: =COUNTIF('All Cases'!$D$2:$D$323,A8) -> 7 | C8: =COUNTIFS('All Cases'!$D$2:$D$323,A8,'All Cases'!$F$2:$F$323,"Dismissed/Withdrawn") -> 4 | D8: =COUNTIFS('All Cases'!$D$2:$D$323,A8,'All Cases'!$F$2:$F$323,"Default Judgment") -> 0 | E8: =COUNTIFS('All Cases'!$D$2:$D$323,A8,'All Cases'!$F$2:$F$323,"Active") -> 3 | F8: =COUNTIFS('All Cases'!$D$2:$D$323,A8,'All Cases'!$F$2:$F$323,"Merits/Judgment") -> 0 | G8: =COUNTIFS('All Cases'!$D$2:$D$323,A8,'All Cases'!$F$2:$F$323,"Other/Unknown") -> 0
A9: Hon. Terry A. Green | B9: =COUNTIF('All Cases'!$D$2:$D$323,A9) -> 7 | C9: =COUNTIFS('All Cases'!$D$2:$D$323,A9,'All Cases'!$F$2:$F$323,"Dismissed/Withdrawn") -> 6 | D9: =COUNTIFS('All Cases'!$D$2:$D$323,A9,'All Cases'!$F$2:$F$323,"Default Judgment") -> 1 | E9: =COUNTIFS('All Cases'!$D$2:$D$323,A9,'All Cases'!$F$2:$F$323,"Active") -> 0 | F9: =COUNTIFS('All Cases'!$D$2:$D$323,A9,'All Cases'!$F$2:$F$323,"Merits/Judgment") -> 0 | G9: =COUNTIFS('All Cases'!$D$2:$D$323,A9,'All Cases'!$F$2:$F$323,"Other/Unknown") -> 0
A10: Hon. Elizabeth Allen White | B10: =COUNTIF('All Cases'!$D$2:$D$323,A10) -> 6 | C10: =COUNTIFS('All Cases'!$D$2:$D$323,A10,'All Cases'!$F$2:$F$323,"Dismissed/Withdrawn") -> 4 | D10: =COUNTIFS('All Cases'!$D$2:$D$323,A10,'All Cases'!$F$2:$F$323,"Default Judgment") -> 1 | E10: =COUNTIFS('All Cases'!$D$2:$D$323,A10,'All Cases'!$F$2:$F$323,"Active") -> 0 | F10: =COUNTIFS('All Cases'!$D$2:$D$323,A10,'All Cases'!$F$2:$F$323,"Merits/Judgment") -> 1 | G10: =COUNTIFS('All Cases'!$D$2:$D$323,A10,'All Cases'!$F$2:$F$323,"Other/Unknown") -> 0
A11: Hon. Susan Bryant-Deason | B11: =COUNTIF('All Cases'!$D$2:$D$323,A11) -> 6 | C11: =COUNTIFS('All Cases'!$D$2:$D$323,A11,'All Cases'!$F$2:$F$323,"Dismissed/Withdrawn") -> 5 | D11: =COUNTIFS('All Cases'!$D$2:$D$323,A11,'All Cases'!$F$2:$F$323,"Default Judgment") -> 1 | E11: =COUNTIFS('All Cases'!$D$2:$D$323,A11,'All Cases'!$F$2:$F$323,"Active") -> 0 | F11: =COUNTIFS('All Cases'!$D$2:$D$323,A11,'All Cases'!$F$2:$F$323,"Merits/Judgment") -> 0 | G11: =COUNTIFS('All Cases'!$D$2:$D$323,A11,'All Cases'!$F$2:$F$323,"Other/Unknown") -> 0
A12: Hon. Mel Red Recana | B12: =COUNTIF('All Cases'!$D$2:$D$323,A12) -> 5 | C12: =COUNTIFS('All Cases'!$D$2:$D$323,A12,'All Cases'!$F$2:$F$323,"Dismissed/Withdrawn") -> 4 | D12: =COUNTIFS('All Cases'!$D$2:$D$323,A12,'All Cases'!$F$2:$F$323,"Default Judgment") -> 0 | E12: =COUNTIFS('All Cases'!$D$2:$D$323,A12,'All Cases'!$F$2:$F$323,"Active") -> 0 | F12: =COUNTIFS('All Cases'!$D$2:$D$323,A12,'All Cases'!$F$2:$F$323,"Merits/Judgment") -> 1 | G12: =COUNTIFS('All Cases'!$D$2:$D$323,A12,'All Cases'!$F$2:$F$323,"Other/Unknown") -> 0
A13: Hon. Ronald M. Sohigian | B13: =COUNTIF('All Cases'!$D$2:$D$323,A13) -> 5 | C13: =COUNTIFS('All Cases'!$D$2:$D$323,A13,'All Cases'!$F$2:$F$323,"Dismissed/Withdrawn") -> 3 | D13: =COUNTIFS('All Cases'!$D$2:$D$323,A13,'All Cases'!$F$2:$F$323,"Default Judgment") -> 1 | E13: =COUNTIFS('All Cases'!$D$2:$D$323,A13,'All Cases'!$F$2:$F$323,"Active") -> 0 | F13: =COUNTIFS('All Cases'!$D$2:$D$323,A13,'All Cases'!$F$2:$F$323,"Merits/Judgment") -> 0 | G13: =COUNTIFS('All Cases'!$D$2:$D$323,A13,'All Cases'!$F$2:$F$323,"Other/Unknown") -> 1
A14: Hon. Robert Leslie Hess | B14: =COUNTIF('All Cases'!$D$2:$D$323,A14) -> 5 | C14: =COUNTIFS('All Cases'!$D$2:$D$323,A14,'All Cases'!$F$2:$F$323,"Dismissed/Withdrawn") -> 4 | D14: =COUNTIFS('All Cases'!$D$2:$D$323,A14,'All Cases'!$F$2:$F$323,"Default Judgment") -> 0 | E14: =COUNTIFS('All Cases'!$D$2:$D$323,A14,'All Cases'!$F$2:$F$323,"Active") -> 0 | F14: =COUNTIFS('All Cases'!$D$2:$D$323,A14,'All Cases'!$F$2:$F$323,"Merits/Judgment") -> 1 | G14: =COUNTIFS('All Cases'!$D$2:$D$323,A14,'All Cases'!$F$2:$F$323,"Other/Unknown") -> 0
A15: Hon. Richard L. Fruin, Jr. | B15: =COUNTIF('All Cases'!$D$2:$D$323,A15) -> 5 | C15: =COUNTIFS('All Cases'!$D$2:$D$323,A15,'All Cases'!$F$2:$F$323,"Dismissed/Withdrawn") -> 4 | D15: =COUNTIFS('All Cases'!$D$2:$D$323,A15,'All Cases'!$F$2:$F$323,"Default Judgment") -> 1 | E15: =COUNTIFS('All Cases'!$D$2:$D$323,A15,'All Cases'!$F$2:$F$323,"Active") -> 0 | F15: =COUNTIFS('All Cases'!$D$2:$D$323,A15,'All Cases'!$F$2:$F$323,"Merits/Judgment") -> 0 | G15: =COUNTIFS('All Cases'!$D$2:$D$323,A15,'All Cases'!$F$2:$F$323,"Other/Unknown") -> 0
... A162: Hon. Frederick C. Shaller | B162: =COUNTIF('All Cases'!$D$2:$D$323,A162) -> 1 | C162: =COUNTIFS('All Cases'!$D$2:$D$323,A162,'All Cases'!$F$2:$F$323,"Dismissed/Withdrawn") -> 1 | D162: =COUNTIFS('All Cases'!$D$2:$D$323,A162,'All Cases'!$F$2:$F$323,"Default Judgment") -> 0 | E162: =COUNTIFS('All Cases'!$D$2:$D$323,A162,'All Cases'!$F$2:$F$323,"Active") -> 0 | F162: =COUNTIFS('All Cases'!$D$2:$D$323,A162,'All Cases'!$F$2:$F$323,"Merits/Judgment") -> 0 | G162: =COUNTIFS('All Cases'!$D$2:$D$323,A162,'All Cases'!$F$2:$F$323,"Other/Unknown") -> 0

Sheet Disposition Summary
A1: By raw Trellis disposition
A3: Disposition | B3: Count
A4: Dismissal | B4: =COUNTIF('All Cases'!$E$2:$E$323,A4) -> 170
A5: Voluntary Dismissal | B5: =COUNTIF('All Cases'!$E$2:$E$323,A5) -> 34
A6: Active | B6: =COUNTIF('All Cases'!$E$2:$E$323,A6) -> 31
A7: Default Judgment | B7: =COUNTIF('All Cases'!$E$2:$E$323,A7) -> 28
A8: Unknown | B8: =COUNTIF('All Cases'!$E$2:$E$323,A8) -> 11
A9: Other | B9: =COUNTIF('All Cases'!$E$2:$E$323,A9) -> 7
A10: Want of Prosecution | B10: =COUNTIF('All Cases'!$E$2:$E$323,A10) -> 6
A11: Judgment (Other) | B11: =COUNTIF('All Cases'!$E$2:$E$323,A11) -> 6
A12: Jury Verdict | B12: =COUNTIF('All Cases'!$E$2:$E$323,A12) -> 6
A13: Non-Jury Verdict | B13: =COUNTIF('All Cases'!$E$2:$E$323,A13) -> 4
A14: Removal | B14: =COUNTIF('All Cases'!$E$2:$E$323,A14) -> 4
A15: Consolidation | B15: =COUNTIF('All Cases'!$E$2:$E$323,A15) -> 3
... A24: Stayed | B24: =COUNTIF('All Cases'!$E$2:$E$323,A24) -> 1
A25: TOTAL | B25: =SUM(B4:B24) -> 322
A28: By Outcome Bucket
A29: Bucket | B29: Count
A30: Dismissed/Withdrawn | B30: =COUNTIF('All Cases'!$F$2:$F$323,A30) -> 210
A31: Default Judgment | B31: =COUNTIF('All Cases'!$F$2:$F$323,A31) -> 28
A32: Active | B32: =COUNTIF('All Cases'!$F$2:$F$323,A32) -> 31
A33: Merits/Judgment | B33: =COUNTIF('All Cases'!$F$2:$F$323,A33) -> 19
A34: Other/Unknown | B34: =COUNTIF('All Cases'!$F$2:$F$323,A34) -> 34
A35: TOTAL | B35: =SUM(B30:B34) -> 322

Sheet Liberty BC606196
A1: LIBERTY MEDIA GROUP LLC ET AL v. CINECAUSE LLC ET AL — BC606196
A3: Court | B3: Stanley Mosk Courthouse (LA County Superior)
A4: Judge | B4: Hon. Michael P. Linfield (civil)
A5: Filed | B5: Jan 5, 2016
A6: Disposition | B6: Court-Ordered Dismissal — Other
A7: Verdict | B7: Unclassified
A8: Practice Area / Matter | B8: Commercial / Breach of Contract
A9: Plaintiffs | B9: Liberty Media Group LLC; Community Redevelopment Association LLC; General Barricade LLC
A10: Plaintiffs’ counsel | B10: Freedman + Taitelman LLP
A11: Source | B11: 130-page Trellis docket (refreshed May 23, 2026)
A12: Note | B12: This is the one matter with full docket depth — the place to read actual motion-by-motion outcomes. Say the word and I’ll extract the docket timeline into its own tab.
A14: Defendants (party-level disposition from docket)
A15: Defendant | B15: Status
A16: Barnett, Courtney | B16: Dismissed
A17: Cinecause LLC | B17: Active party (Ps)
A18: Fitzgerald, Jon | B18: Dismissed
A19: Gilead Sciences Inc | B19: Active party (Ps)
A20: Goldenvoice LLC
A21: Grant, Lalanii Rochelle | B21: Dismissed
A22: Hollywood Film Festival | B22: Dismissed
A23: Hozier-Byrne, Andrew (Hozier)
A24: Jarvis, Shaun | B24: Dismissed
A25: Moderne Communications Inc | B25: Doe 1
A26: Mosaic L.A. | B26: Active party (Ps)
A27: Parks, Brad | B27: Dismissed
A28: Postergiant Inc | B28: Doe 2
A29: One-Distribution Company LLC
A30: K-Swiss Global Brands | B30: Active party (Ps)
